Workbook

Sheet Transactions
A1: transaction_id | B1: transaction_date | C1: customer_id | D1: department | E1: product_sku | F1: product_name | G1: quantity | H1: unit_price | I1: discount_pct | J1: total_cost | K1: payment_method | L1: sales_channel | M1: register_id
A2: 101047 | B2: 45290 | C2: 47786 | D2: Electronics | E2: EL-102 | F2: Bluetooth Headphones | G2: 2 | H2: 79.99 | J2: 159.98 | K2: Credit Card | L2: In-Store | M2: REG-12
A3: 101291 | B3: 45160 | C3: 83378 | D3: PHARMACY | E3: PH-001 | F3: Ibuprofen 200ct | G3: 5 | H3: 9.99 | J3: 49.95 | K3: Cash | L3: Curbside Pickup | M3: REG-19
A4: 101812 | B4: 44683 | C4: 60430 | D4: Furniture | E4: FU-001 | F4: Folding Chair | G4: 1 | H4: 29.74 | I4: 0.15 | J4: 25.28 | K4: Credit Card | L4: In-Store | M4: REG-6
A5: 102088 | B5: 45078 | C5: 80498 | D5: Toys | E5: TY-203 | F5: Nerf Gun | G5: 5 | H5: 24.99 | J5: 124.95 | K5: EBT | L5: In-Store | M5: REG-14
A6: 102306 | B6: 44998 | C6: 62555 | D6: Electronics | E6: EL-303 | F6: USB-C Hub | G6: 3 | H6: 34.99 | J6: 104.97 | K6: Debit Card | L6: Online | M6: REG-12
A7: 102465 | B7: 44900 | C7: 78782 | D7: Toys | E7: TY-304 | F7: Board Game | G7: 5 | H7: 20.99 | I7: 0.3 | J7: 73.46 | K7: EBT | L7: In-Store | M7: REG-14
A8: 102502 | B8: 44868 | D8: Pharmacy | E8: PH-304 | F8: Bandage Assortment | G8: 2 | H8: 4.49 | I8: 0.25 | J8: 6.74 | K8: Cash | L8: In-Store | M8: REG-15
A9: 102533 | B9: 45555 | D9: Grocery | E9: GR-007 | F9: Pasta 1lb | G9: 1 | H9: 1.34 | I9: 0.25 | J9: 1.01 | K9: Credit Card | L9: In-Store | M9: REG-11
A10: 103055 | B10: 45048 | C10: 95915 | D10: Beauty | E10: BE-203 | F10: Mascara | G10: 2 | H10: 8.99 | J10: 17.98 | K10: Debit Card | L10: Online | M10: REG-11
A11: 103292 | B11: 45196 | C11: 46193 | D11: Furniture | E11: FU-203 | F11: Desk Lamp | G11: 1 | H11: 19.59 | I11: 0.3 | J11: 13.71 | K11: Gift Card | L11: Online | M11: REG-16
A12: 103300 | B12: 45486 | C12: 19709 | D12: Electronics | E12: EL-707 | F12: Tablet 10" | G12: 3 | H12: 230.99 | I12: 0.3 | J12: 485.08 | K12: Debit Card | L12: Online | M12: REG-13
A13: 103496 | B13: 45395 | C13: 42392 | D13: Pharmacy | E13: PH-405 | F13: Hand Sanitizer 8oz | G13: 1 | H13: 3.39 | I13: 0.15 | J13: 2.88 | K13: Debit Card | L13: In-Store | M13: REG-6
A14: 103506 | B14: 45367 | C14: 91356 | D14: Furniture | E14: FU-304 | F14: Storage Ottoman | G14: 5 | H14: 52.24 | I14: 0.05 | J14: 248.14 | K14: Credit Card | L14: In-Store | M14: REG-18
A15: 103735 | B15: 44600 | D15: Grocery | E15: GR-007 | F15: Pasta 1lb | G15: 2 | H15: 1.79 | J15: 3.58 | K15: Credit Card | L15: In-Store | M15: REG-12
A16: 104478 | B16: 45165 | C16: 86184 | D16: Automotive | E16: AU-203 | F16: Windshield Washer Fluid | G16: 1 | H16: 4.99 | J16: 4.99 | K16: Check | L16: In-Store | M16: REG-1
A17: 104488 | B17: 44889 | C17: 47751 | D17: Automotive | E17: AU-203 | F17: Windshield Washer Fluid | G17: 3 | H17: 4.74 | I17: 0.05 | J17: 13.51 | K17: Debit Card | L17: Online | M17: REG-12
A18: 104523 | B18: 45319 | C18: 10364 | D18: Automotive | E18: AU-001 | F18: Motor Oil 5qt | G18: 2 | H18: 19.99 | I18: 0.2 | J18: 31.98 | K18: Credit Card | L18: Online | M18: REG-16
A19: 104855 | B19: 45547 | C19: 48062 | D19: Furniture | E19: FU-102 | F19: Bookshelf 5-Tier | G19: 2 | H19: 89.99 | J19: 179.98 | K19: Debit Card | L19: In-Store | M19: REG-6
A20: 105337 | B20: 44814 | C20: 42955 | D20: Electronics | E20: EL-303 | F20: USB-C Hub | G20: 2 | H20: 34.99 | J20: 69.98 | K20: Credit Card | L20: Online | M20: REG-13
A21: 105411 | B21: 44805 | C21: 73284 | D21: Toys | E21: TY-506 | F21: RC Car | G21: 1 | H21: 33.99 | I21: 0.15 | J21: 28.89 | K21: Debit Card | L21: Online | M21: REG-15
A22: 105767 | B22: 44604 | C22: 15863 | D22: Grocery | E22: GR-002 | F22: White Bread | G22: 3 | H22: 2.09 | I22: 0.3 | J22: 4.39 | K22: Gift Card | L22: In-Store | M22: REG-20
A23: 105891 | B23: 45425 | C23: 64264 | D23: Electronics | E23: TV-001 | F23: 4K Smart TV 55" | G23: 1 | H23: 499.99 | J23: 499.99 | K23: Debit Card | L23: Curbside Pickup | M23: REG-19
A24: 105898 | B24: 45614 | D24: Electronics | E24: EL-606 | F24: Smart Speaker | G24: 3 | H24: 89.99 | J24: 269.97 | K24: Credit Card | L24: In-Store | M24: REG-7
A25: 105910 | B25: 45026 | C25: 73703 | D25: Sports | E25: SP-203 | F25: Water Bottle 32oz | G25: 3 | H25: 11.89 | I25: 0.3 | J25: 24.97 | K25: Debit Card | L25: In-Store | M25: REG-16
A26: 105960 | B26: 45338 | C26: 70702 | D26: Home & Garden | E26: HG-203 | F26: Scented Candle | G26: 1 | H26: 9.09 | I26: 0.3 | J26: 6.36 | K26: Cash | L26: In-Store | M26: REG-15
A27: 106029 | B27: 45581 | C27: 96438 | D27: Toys | E27: TY-001 | F27: LEGO City Set | G27: 2 | H27: 37.49 | I27: 0.25 | J27: 56.24 | K27: Credit Card | L27: In-Store | M27: REG-10
A28: 106047 | B28: 44876 | C28: 81600 | D28: Grocery | E28: GR-006 | F28: Greek Yogurt 32oz | G28: 1 | H28: 4.72 | J28: 4.72 | K28: Cash | L28: In-Store | M28: REG-7
A29: 106263 | B29: 44902 | C29: 95178 | D29: Grocery | E29: GR-008 | F29: Canned Tomatoes | G29: 5 | H29: 0.9 | I29: 0.3 | J29: 3.15 | K29: Mobile Pay | L29: In-Store | M29: REG-14
A30: 106543 | B30: 45204 | C30: 88674 | D30: Automotive | E30: AU-203 | F30: Windshield Washer Fluid | G30: 1 | H30: 3.99 | I30: 0.2 | J30: 3.19 | K30: Debit Card | L30: In-Store | M30: REG-9
A31: 106587 | B31: 45594 | C31: 94688 | D31: Clothing | E31: CL-506 | F31: Yoga Pants | G31: 4 | H31: 27.99 | J31: 111.96 | K31: Credit Card | L31: In-Store | M31: REG-1
A32: 106747 | B32: 45229 | C32: 22687 | D32: Automotive | E32: AU-001 | F32: Motor Oil 5qt | G32: 2 | H32: 19.99 | I32: 0.2 | J32: 31.98 | K32: Cash | L32: Online | M32: REG-20
A33: 106802 | B33: 45075 | C33: 54297 | D33: Toys | E33: TY-304 | F33: Board Game | G33: 1 | H33: 28.49 | I33: 0.05 | J33: 27.07 | K33: Credit Card | L33: Online | M33: REG-10
A34: 106949 | B34: 45526 | C34: 77873 | D34: Sports | E34: SP-001 | F34: Yoga Mat | G34: 2 | H34: 22.99 | J34: 45.98 | K34: Check | L34: Online | M34: REG-8
A35: 106959 | B35: 45625 | C35: 17057 | D35: PHARMACY | E35: PH-405 | F35: Hand Sanitizer 8oz | G35: 2 | H35: 3.39 | I35: 0.15 | J35: 5.76 | K35: EBT | L35: Online | M35: REG-17
A36: 107239 | B36: 44834 | C36: 29478 | D36: Grocery | E36: GR-002 | F36: White Bread | G36: 1 | H36: 2.09 | I36: 0.3 | J36: 1.46 | K36: Cash | L36: In-Store | M36: REG-6
A37: 107432 | B37: 44917 | C37: 24560 | D37: Electronics | E37: EL-505 | F37: Wireless Charger | G37: 5 | H37: 23.99 | I37: 0.2 | J37: 95.96 | K37: Mobile Pay | L37: In-Store | M37: REG-1
A38: 107461 | B38: 45309 | C38: 64862 | D38: GROCERY | E38: GR-010 | F38: Eggs 12ct | G38: 1 | H38: 3.49 | J38: 3.49 | K38: Debit Card | L38: In-Store | M38: REG-10
A39: 107567 | B39: 44771 | C39: 84944 | D39: Beauty | E39: BE-001 | F39: Shampoo 16oz | G39: 5 | H39: 6.99 | J39: 34.95 | K39: Debit Card | L39: In-Store | M39: REG-7
A40: 107786 | B40: 45135 | C40: 68036 | D40: Automotive | E40: AU-304 | F40: Car Phone Mount | G40: 1 | H40: 11.24 | I40: 0.25 | J40: 8.43 | K40: Cash | L40: In-Store | M40: REG-18
...

Sheet Transactions (Cleaned)
A1: transaction_id | B1: transaction_date | C1: customer_id | D1: department | E1: product_sku | F1: product_name | G1: quantity | H1: unit_price | I1: discount_pct | J1: total_cost | K1: payment_method | L1: sales_channel | M1: register_id
A2: 101047 | B2: 45290 | C2: 47786 | D2: =PROPER(Transactions!D2) -> Electronics | E2: EL-102 | F2: Bluetooth Headphones | G2: 2 | H2: 79.99 | I2: =IF(Transactions!I2="",0,Transactions!I2) -> 0 | J2: =(H2*G2)*(1-I2) -> 159.98 | K2: Credit Card | L2: In-Store | M2: =REPLACE(Transactions!M2,1,4,"") -> 12
A3: 101291 | B3: 45160 | C3: 83378 | D3: =PROPER(Transactions!D3) -> Pharmacy | E3: PH-001 | F3: Ibuprofen 200ct | G3: 5 | H3: 9.99 | I3: =IF(Transactions!I3="",0,Transactions!I3) -> 0 | J3: =(H3*G3)*(1-I3) -> 49.95 | K3: Cash | L3: Curbside Pickup | M3: =REPLACE(Transactions!M3,1,4,"") -> 19
A4: 101812 | B4: 44683 | C4: 60430 | D4: =PROPER(Transactions!D4) -> Furniture | E4: FU-001 | F4: Folding Chair | G4: 1 | H4: 29.74 | I4: =IF(Transactions!I4="",0,Transactions!I4) -> 0.15 | J4: =(H4*G4)*(1-I4) -> 25.279 | K4: Credit Card | L4: In-Store | M4: =REPLACE(Transactions!M4,1,4,"") -> 6
A5: 102088 | B5: 45078 | C5: 80498 | D5: =PROPER(Transactions!D5) -> Toys | E5: TY-203 | F5: Nerf Gun | G5: 5 | H5: 24.99 | I5: =IF(Transactions!I5="",0,Transactions!I5) -> 0 | J5: =(H5*G5)*(1-I5) -> 124.95 | K5: EBT | L5: In-Store | M5: =REPLACE(Transactions!M5,1,4,"") -> 14
A6: 102306 | B6: 44998 | C6: 62555 | D6: =PROPER(Transactions!D6) -> Electronics | E6: EL-303 | F6: USB-C Hub | G6: 3 | H6: 34.99 | I6: =IF(Transactions!I6="",0,Transactions!I6) -> 0 | J6: =(H6*G6)*(1-I6) -> 104.97 | K6: Debit Card | L6: Online | M6: =REPLACE(Transactions!M6,1,4,"") -> 12
A7: 102465 | B7: 44900 | C7: 78782 | D7: =PROPER(Transactions!D7) -> Toys | E7: TY-304 | F7: Board Game | G7: 5 | H7: 20.99 | I7: =IF(Transactions!I7="",0,Transactions!I7) -> 0.3 | J7: =(H7*G7)*(1-I7) -> 73.465 | K7: EBT | L7: In-Store | M7: =REPLACE(Transactions!M7,1,4,"") -> 14
A8: 102502 | B8: 44868 | D8: =PROPER(Transactions!D8) -> Pharmacy | E8: PH-304 | F8: Bandage Assortment | G8: 2 | H8: 4.49 | I8: =IF(Transactions!I8="",0,Transactions!I8) -> 0.25 | J8: =(H8*G8)*(1-I8) -> 6.735 | K8: Cash | L8: In-Store | M8: =REPLACE(Transactions!M8,1,4,"") -> 15
A9: 102533 | B9: 45555 | D9: =PROPER(Transactions!D9) -> Grocery | E9: GR-007 | F9: Pasta 1lb | G9: 1 | H9: 1.34 | I9: =IF(Transactions!I9="",0,Transactions!I9) -> 0.25 | J9: =(H9*G9)*(1-I9) -> 1.005 | K9: Credit Card | L9: In-Store | M9: =REPLACE(Transactions!M9,1,4,"") -> 11
A10: 103055 | B10: 45048 | C10: 95915 | D10: =PROPER(Transactions!D10) -> Beauty | E10: BE-203 | F10: Mascara | G10: 2 | H10: 8.99 | I10: =IF(Transactions!I10="",0,Transactions!I10) -> 0 | J10: =(H10*G10)*(1-I10) -> 17.98 | K10: Debit Card | L10: Online | M10: =REPLACE(Transactions!M10,1,4,"") -> 11
A11: 103292 | B11: 45196 | C11: 46193 | D11: =PROPER(Transactions!D11) -> Furniture | E11: FU-203 | F11: Desk Lamp | G11: 1 | H11: 19.59 | I11: =IF(Transactions!I11="",0,Transactions!I11) -> 0.3 | J11: =(H11*G11)*(1-I11) -> 13.713 | K11: Gift Card | L11: Online | M11: =REPLACE(Transactions!M11,1,4,"") -> 16
A12: 103300 | B12: 45486 | C12: 19709 | D12: =PROPER(Transactions!D12) -> Electronics | E12: EL-707 | F12: Tablet 10" | G12: 3 | H12: 230.99 | I12: =IF(Transactions!I12="",0,Transactions!I12) -> 0.3 | J12: =(H12*G12)*(1-I12) -> 485.079 | K12: Debit Card | L12: Online | M12: =REPLACE(Transactions!M12,1,4,"") -> 13
A13: 103496 | B13: 45395 | C13: 42392 | D13: =PROPER(Transactions!D13) -> Pharmacy | E13: PH-405 | F13: Hand Sanitizer 8oz | G13: 1 | H13: 3.39 | I13: =IF(Transactions!I13="",0,Transactions!I13) -> 0.15 | J13: =(H13*G13)*(1-I13) -> 2.8815 | K13: Debit Card | L13: In-Store | M13: =REPLACE(Transactions!M13,1,4,"") -> 6
A14: 103506 | B14: 45367 | C14: 91356 | D14: =PROPER(Transactions!D14) -> Furniture | E14: FU-304 | F14: Storage Ottoman | G14: 5 | H14: 52.24 | I14: =IF(Transactions!I14="",0,Transactions!I14) -> 0.05 | J14: =(H14*G14)*(1-I14) -> 248.14 | K14: Credit Card | L14: In-Store | M14: =REPLACE(Transactions!M14,1,4,"") -> 18
A15: 103735 | B15: 44600 | D15: =PROPER(Transactions!D15) -> Grocery | E15: GR-007 | F15: Pasta 1lb | G15: 2 | H15: 1.79 | I15: =IF(Transactions!I15="",0,Transactions!I15) -> 0 | J15: =(H15*G15)*(1-I15) -> 3.58 | K15: Credit Card | L15: In-Store | M15: =REPLACE(Transactions!M15,1,4,"") -> 12
A16: 104478 | B16: 45165 | C16: 86184 | D16: =PROPER(Transactions!D16) -> Automotive | E16: AU-203 | F16: Windshield Washer Fluid | G16: 1 | H16: 4.99 | I16: =IF(Transactions!I16="",0,Transactions!I16) -> 0 | J16: =(H16*G16)*(1-I16) -> 4.99 | K16: Check | L16: In-Store | M16: =REPLACE(Transactions!M16,1,4,"") -> 1
A17: 104488 | B17: 44889 | C17: 47751 | D17: =PROPER(Transactions!D17) -> Automotive | E17: AU-203 | F17: Windshield Washer Fluid | G17: 3 | H17: 4.74 | I17: =IF(Transactions!I17="",0,Transactions!I17) -> 0.05 | J17: =(H17*G17)*(1-I17) -> 13.509 | K17: Debit Card | L17: Online | M17: =REPLACE(Transactions!M17,1,4,"") -> 12
A18: 104523 | B18: 45319 | C18: 10364 | D18: =PROPER(Transactions!D18) -> Automotive | E18: AU-001 | F18: Motor Oil 5qt | G18: 2 | H18: 19.99 | I18: =IF(Transactions!I18="",0,Transactions!I18) -> 0.2 | J18: =(H18*G18)*(1-I18) -> 31.984 | K18: Credit Card | L18: Online | M18: =REPLACE(Transactions!M18,1,4,"") -> 16
A19: 104855 | B19: 45547 | C19: 48062 | D19: =PROPER(Transactions!D19) -> Furniture | E19: FU-102 | F19: Bookshelf 5-Tier | G19: 2 | H19: 89.99 | I19: =IF(Transactions!I19="",0,Transactions!I19) -> 0 | J19: =(H19*G19)*(1-I19) -> 179.98 | K19: Debit Card | L19: In-Store | M19: =REPLACE(Transactions!M19,1,4,"") -> 6
A20: 105337 | B20: 44814 | C20: 42955 | D20: =PROPER(Transactions!D20) -> Electronics | E20: EL-303 | F20: USB-C Hub | G20: 2 | H20: 34.99 | I20: =IF(Transactions!I20="",0,Transactions!I20) -> 0 | J20: =(H20*G20)*(1-I20) -> 69.98 | K20: Credit Card | L20: Online | M20: =REPLACE(Transactions!M20,1,4,"") -> 13
A21: 105411 | B21: 44805 | C21: 73284 | D21: =PROPER(Transactions!D21) -> Toys | E21: TY-506 | F21: RC Car | G21: 1 | H21: 33.99 | I21: =IF(Transactions!I21="",0,Transactions!I21) -> 0.15 | J21: =(H21*G21)*(1-I21) -> 28.8915 | K21: Debit Card | L21: Online | M21: =REPLACE(Transactions!M21,1,4,"") -> 15
A22: 105767 | B22: 44604 | C22: 15863 | D22: =PROPER(Transactions!D22) -> Grocery | E22: GR-002 | F22: White Bread | G22: 3 | H22: 2.09 | I22: =IF(Transactions!I22="",0,Transactions!I22) -> 0.3 | J22: =(H22*G22)*(1-I22) -> 4.389 | K22: Gift Card | L22: In-Store | M22: =REPLACE(Transactions!M22,1,4,"") -> 20
A23: 105891 | B23: 45425 | C23: 64264 | D23: =PROPER(Transactions!D23) -> Electronics | E23: TV-001 | F23: 4K Smart TV 55" | G23: 1 | H23: 499.99 | I23: =IF(Transactions!I23="",0,Transactions!I23) -> 0 | J23: =(H23*G23)*(1-I23) -> 499.99 | K23: Debit Card | L23: Curbside Pickup | M23: =REPLACE(Transactions!M23,1,4,"") -> 19
A24: 105898 | B24: 45614 | D24: =PROPER(Transactions!D24) -> Electronics | E24: EL-606 | F24: Smart Speaker | G24: 3 | H24: 89.99 | I24: =IF(Transactions!I24="",0,Transactions!I24) -> 0 | J24: =(H24*G24)*(1-I24) -> 269.97 | K24: Credit Card | L24: In-Store | M24: =REPLACE(Transactions!M24,1,4,"") -> 7
A25: 105910 | B25: 45026 | C25: 73703 | D25: =PROPER(Transactions!D25) -> Sports | E25: SP-203 | F25: Water Bottle 32oz | G25: 3 | H25: 11.89 | I25: =IF(Transactions!I25="",0,Transactions!I25) -> 0.3 | J25: =(H25*G25)*(1-I25) -> 24.969 | K25: Debit Card | L25: In-Store | M25: =REPLACE(Transactions!M25,1,4,"") -> 16
A26: 105960 | B26: 45338 | C26: 70702 | D26: =PROPER(Transactions!D26) -> Home & Garden | E26: HG-203 | F26: Scented Candle | G26: 1 | H26: 9.09 | I26: =IF(Transactions!I26="",0,Transactions!I26) -> 0.3 | J26: =(H26*G26)*(1-I26) -> 6.363 | K26: Cash | L26: In-Store | M26: =REPLACE(Transactions!M26,1,4,"") -> 15
A27: 106029 | B27: 45581 | C27: 96438 | D27: =PROPER(Transactions!D27) -> Toys | E27: TY-001 | F27: LEGO City Set | G27: 2 | H27: 37.49 | I27: =IF(Transactions!I27="",0,Transactions!I27) -> 0.25 | J27: =(H27*G27)*(1-I27) -> 56.235 | K27: Credit Card | L27: In-Store | M27: =REPLACE(Transactions!M27,1,4,"") -> 10
A28: 106047 | B28: 44876 | C28: 81600 | D28: =PROPER(Transactions!D28) -> Grocery | E28: GR-006 | F28: Greek Yogurt 32oz | G28: 1 | H28: 4.72 | I28: =IF(Transactions!I28="",0,Transactions!I28) -> 0 | J28: =(H28*G28)*(1-I28) -> 4.72 | K28: Cash | L28: In-Store | M28: =REPLACE(Transactions!M28,1,4,"") -> 7
A29: 106263 | B29: 44902 | C29: 95178 | D29: =PROPER(Transactions!D29) -> Grocery | E29: GR-008 | F29: Canned Tomatoes | G29: 5 | H29: 0.9 | I29: =IF(Transactions!I29="",0,Transactions!I29) -> 0.3 | J29: =(H29*G29)*(1-I29) -> 3.15 | K29: Mobile Pay | L29: In-Store | M29: =REPLACE(Transactions!M29,1,4,"") -> 14
A30: 106543 | B30: 45204 | C30: 88674 | D30: =PROPER(Transactions!D30) -> Automotive | E30: AU-203 | F30: Windshield Washer Fluid | G30: 1 | H30: 3.99 | I30: =IF(Transactions!I30="",0,Transactions!I30) -> 0.2 | J30: =(H30*G30)*(1-I30) -> 3.192 | K30: Debit Card | L30: In-Store | M30: =REPLACE(Transactions!M30,1,4,"") -> 9
A31: 106587 | B31: 45594 | C31: 94688 | D31: =PROPER(Transactions!D31) -> Clothing | E31: CL-506 | F31: Yoga Pants | G31: 4 | H31: 27.99 | I31: =IF(Transactions!I31="",0,Transactions!I31) -> 0 | J31: =(H31*G31)*(1-I31) -> 111.96 | K31: Credit Card | L31: In-Store | M31: =REPLACE(Transactions!M31,1,4,"") -> 1
A32: 106747 | B32: 45229 | C32: 22687 | D32: =PROPER(Transactions!D32) -> Automotive | E32: AU-001 | F32: Motor Oil 5qt | G32: 2 | H32: 19.99 | I32: =IF(Transactions!I32="",0,Transactions!I32) -> 0.2 | J32: =(H32*G32)*(1-I32) -> 31.984 | K32: Cash | L32: Online | M32: =REPLACE(Transactions!M32,1,4,"") -> 20
A33: 106802 | B33: 45075 | C33: 54297 | D33: =PROPER(Transactions!D33) -> Toys | E33: TY-304 | F33: Board Game | G33: 1 | H33: 28.49 | I33: =IF(Transactions!I33="",0,Transactions!I33) -> 0.05 | J33: =(H33*G33)*(1-I33) -> 27.0655 | K33: Credit Card | L33: Online | M33: =REPLACE(Transactions!M33,1,4,"") -> 10
A34: 106949 | B34: 45526 | C34: 77873 | D34: =PROPER(Transactions!D34) -> Sports | E34: SP-001 | F34: Yoga Mat | G34: 2 | H34: 22.99 | I34: =IF(Transactions!I34="",0,Transactions!I34) -> 0 | J34: =(H34*G34)*(1-I34) -> 45.98 | K34: Check | L34: Online | M34: =REPLACE(Transactions!M34,1,4,"") -> 8
A35: 106959 | B35: 45625 | C35: 17057 | D35: =PROPER(Transactions!D35) -> Pharmacy | E35: PH-405 | F35: Hand Sanitizer 8oz | G35: 2 | H35: 3.39 | I35: =IF(Transactions!I35="",0,Transactions!I35) -> 0.15 | J35: =(H35*G35)*(1-I35) -> 5.763 | K35: EBT | L35: Online | M35: =REPLACE(Transactions!M35,1,4,"") -> 17
A36: 107239 | B36: 44834 | C36: 29478 | D36: =PROPER(Transactions!D36) -> Grocery | E36: GR-002 | F36: White Bread | G36: 1 | H36: 2.09 | I36: =IF(Transactions!I36="",0,Transactions!I36) -> 0.3 | J36: =(H36*G36)*(1-I36) -> 1.463 | K36: Cash | L36: In-Store | M36: =REPLACE(Transactions!M36,1,4,"") -> 6
... A57: 110649 | B57: 45296 | C57: 87204 | D57: =PROPER(Transactions!D57) -> Electronics | E57: TV-001 | F57: 4K Smart TV 55" | G57: 1 | H57: 374.99 | I57: =IF(Transactions!I57="",0,Transactions!I57) -> 0.25 | J57: =(H57*G57)*(1-I57) -> 281.2425 | K57: Mobile Pay | L57: In-Store | M57: =REPLACE(Transactions!M57,1,4,"") -> 10
A58: 110666 | B58: 45167 | D58: =PROPER(Transactions!D58) -> Automotive | E58: AU-102 | F58: Car Air Freshener | G58: 2 | H58: 3.49 | I58: =IF(Transactions!I58="",0,Transactions!I58) -> 0 | J58: =(H58*G58)*(1-I58) -> 6.98 | K58: Cash | L58: In-Store | M58: =REPLACE(Transactions!M58,1,4,"") -> 2
A59: 110743 | B59: 44901 | C59: 16675 | D59: =PROPER(Transactions!D59) -> Beauty | E59: BE-304 | F59: Lip Balm 3pk | G59: 1 | H59: 4.24 | I59: =IF(Transactions!I59="",0,Transactions!I59) -> 0.15 | J59: =(H59*G59)*(1-I59) -> 3.604 | K59: Cash | L59: In-Store | M59: =REPLACE(Transactions!M59,1,4,"") -> 18
A60: 111256 | B60: 44659 | C60: 15018 | D60: =PROPER(Transactions!D60) -> Grocery | E60: GR-004 | F60: Bagged Salad Mix | G60: 1 | H60: 3.79 | I60: =IF(Transactions!I60="",0,Transactions!I60) -> 0 | J60: =(H60*G60)*(1-I60) -> 3.79 | K60: Credit Card | L60: In-Store | M60: =REPLACE(Transactions!M60,1,4,"") -> 18
...
